[2024-08-07T14:48:26.849+0000] {local_task_job_runner.py:120} INFO - ::group::Pre task execution logs
[2024-08-07T14:48:26.861+0000] {taskinstance.py:2076} INFO - Dependencies all met for dep_context=non-requeueable deps ti=<TaskInstance: mongodb_to_bigquery.load_products manual__2024-08-07T14:43:12.057956+00:00 [queued]>
[2024-08-07T14:48:26.864+0000] {taskinstance.py:2076} INFO - Dependencies all met for dep_context=requeueable deps ti=<TaskInstance: mongodb_to_bigquery.load_products manual__2024-08-07T14:43:12.057956+00:00 [queued]>
[2024-08-07T14:48:26.864+0000] {taskinstance.py:2306} INFO - Starting attempt 2 of 2
[2024-08-07T14:48:26.870+0000] {taskinstance.py:2330} INFO - Executing <Task(PythonOperator): load_products> on 2024-08-07 14:43:12.057956+00:00
[2024-08-07T14:48:26.878+0000] {warnings.py:112} WARNING - /home/***/.local/lib/python3.12/site-packages/***/task/task_runner/standard_task_runner.py:62: DeprecationWarning: This process (pid=363) is multi-threaded, use of fork() may lead to deadlocks in the child.
  pid = os.fork()

[2024-08-07T14:48:26.880+0000] {standard_task_runner.py:64} INFO - Started process 369 to run task
[2024-08-07T14:48:26.880+0000] {standard_task_runner.py:90} INFO - Running: ['***', 'tasks', 'run', 'mongodb_to_bigquery', 'load_products', 'manual__2024-08-07T14:43:12.057956+00:00', '--job-id', '73', '--raw', '--subdir', 'DAGS_FOLDER/mongodb_to_bigquery.py', '--cfg-path', '/tmp/tmp16vkpbjx']
[2024-08-07T14:48:26.882+0000] {standard_task_runner.py:91} INFO - Job 73: Subtask load_products
[2024-08-07T14:48:26.906+0000] {task_command.py:426} INFO - Running <TaskInstance: mongodb_to_bigquery.load_products manual__2024-08-07T14:43:12.057956+00:00 [running]> on host 721db11e5d12
[2024-08-07T14:48:27.027+0000] {taskinstance.py:2648} INFO - Exporting env vars: AIRFLOW_CTX_DAG_OWNER='***' AIRFLOW_CTX_DAG_ID='mongodb_to_bigquery' AIRFLOW_CTX_TASK_ID='load_products' AIRFLOW_CTX_EXECUTION_DATE='2024-08-07T14:43:12.057956+00:00' AIRFLOW_CTX_TRY_NUMBER='2' AIRFLOW_CTX_DAG_RUN_ID='manual__2024-08-07T14:43:12.057956+00:00'
[2024-08-07T14:48:27.028+0000] {taskinstance.py:430} INFO - ::endgroup::
[2024-08-07T14:48:27.544+0000] {logging_mixin.py:188} INFO - ☑️ Dataset fictive_company already exists
[2024-08-07T14:48:27.900+0000] {logging_mixin.py:188} INFO - ☑️ Table mycenter-425712.fictive_company.products already exists.
[2024-08-07T14:48:27.909+0000] {taskinstance.py:441} INFO - ::group::Post task execution logs
[2024-08-07T14:48:27.910+0000] {taskinstance.py:2905} ERROR - Task failed with exception
Traceback (most recent call last):
  File "/home/airflow/.local/lib/python3.12/site-packages/airflow/models/taskinstance.py", line 465, in _execute_task
    result = _execute_callable(context=context, **execute_callable_kwargs)
             ^^^^^^^^^^^^^^^^^^^^^^^^^^^^^^^^^^^^^^^^^^^^^^^^^^^^^^^^^^^^^
  File "/home/airflow/.local/lib/python3.12/site-packages/airflow/models/taskinstance.py", line 432, in _execute_callable
    return execute_callable(context=context, **execute_callable_kwargs)
           ^^^^^^^^^^^^^^^^^^^^^^^^^^^^^^^^^^^^^^^^^^^^^^^^^^^^^^^^^^^^
  File "/home/airflow/.local/lib/python3.12/site-packages/airflow/models/baseoperator.py", line 401, in wrapper
    return func(self, *args, **kwargs)
           ^^^^^^^^^^^^^^^^^^^^^^^^^^^
  File "/home/airflow/.local/lib/python3.12/site-packages/airflow/operators/python.py", line 235, in execute
    return_value = self.execute_callable()
                   ^^^^^^^^^^^^^^^^^^^^^^^
  File "/home/airflow/.local/lib/python3.12/site-packages/airflow/operators/python.py", line 252, in execute_callable
    return self.python_callable(*self.op_args, **self.op_kwargs)
           ^^^^^^^^^^^^^^^^^^^^^^^^^^^^^^^^^^^^^^^^^^^^^^^^^^^^^
  File "/app/data_engineering/api_connectors/bigquery.py", line 70, in insert_data
    job = self.bigquery_client.load_table_from_dataframe(
          ^^^^^^^^^^^^^^^^^^^^^^^^^^^^^^^^^^^^^^^^^^^^^^^
  File "/home/airflow/.local/lib/python3.12/site-packages/google/cloud/bigquery/client.py", line 2777, in load_table_from_dataframe
    new_job_config.schema = _pandas_helpers.dataframe_to_bq_schema(
                            ^^^^^^^^^^^^^^^^^^^^^^^^^^^^^^^^^^^^^^^
  File "/home/airflow/.local/lib/python3.12/site-packages/google/cloud/bigquery/_pandas_helpers.py", line 482, in dataframe_to_bq_schema
    raise ValueError(
ValueError: bq_schema contains fields not present in dataframe: {'unit_amount', 'category', 'gender', 'title', 'id', 'created_at'}
[2024-08-07T14:48:27.945+0000] {taskinstance.py:1206} INFO - Marking task as FAILED. dag_id=mongodb_to_bigquery, task_id=load_products, run_id=manual__2024-08-07T14:43:12.057956+00:00, execution_date=20240807T144312, start_date=20240807T144826, end_date=20240807T144827
[2024-08-07T14:48:27.968+0000] {standard_task_runner.py:110} ERROR - Failed to execute job 73 for task load_products (bq_schema contains fields not present in dataframe: {'unit_amount', 'category', 'gender', 'title', 'id', 'created_at'}; 369)
[2024-08-07T14:48:28.007+0000] {local_task_job_runner.py:243} INFO - Task exited with return code 1
[2024-08-07T14:48:28.028+0000] {taskinstance.py:3503} INFO - 0 downstream tasks scheduled from follow-on schedule check
[2024-08-07T14:48:28.029+0000] {local_task_job_runner.py:222} INFO - ::endgroup::
