[2024-08-07T14:38:29.932+0000] {local_task_job_runner.py:120} INFO - ::group::Pre task execution logs
[2024-08-07T14:38:29.961+0000] {taskinstance.py:2076} INFO - Dependencies all met for dep_context=non-requeueable deps ti=<TaskInstance: mongodb_to_bigquery.load_orders manual__2024-08-07T14:38:14.199786+00:00 [queued]>
[2024-08-07T14:38:29.966+0000] {taskinstance.py:2076} INFO - Dependencies all met for dep_context=requeueable deps ti=<TaskInstance: mongodb_to_bigquery.load_orders manual__2024-08-07T14:38:14.199786+00:00 [queued]>
[2024-08-07T14:38:29.966+0000] {taskinstance.py:2306} INFO - Starting attempt 1 of 2
[2024-08-07T14:38:29.971+0000] {taskinstance.py:2330} INFO - Executing <Task(PythonOperator): load_orders> on 2024-08-07 14:38:14.199786+00:00
[2024-08-07T14:38:29.981+0000] {warnings.py:112} WARNING - /home/***/.local/lib/python3.12/site-packages/***/task/task_runner/standard_task_runner.py:62: DeprecationWarning: This process (pid=108) is multi-threaded, use of fork() may lead to deadlocks in the child.
  pid = os.fork()

[2024-08-07T14:38:29.987+0000] {standard_task_runner.py:64} INFO - Started process 125 to run task
[2024-08-07T14:38:29.988+0000] {standard_task_runner.py:90} INFO - Running: ['***', 'tasks', 'run', 'mongodb_to_bigquery', 'load_orders', 'manual__2024-08-07T14:38:14.199786+00:00', '--job-id', '66', '--raw', '--subdir', 'DAGS_FOLDER/mongodb_to_bigquery.py', '--cfg-path', '/tmp/tmp5qs68jvn']
[2024-08-07T14:38:29.990+0000] {standard_task_runner.py:91} INFO - Job 66: Subtask load_orders
[2024-08-07T14:38:30.017+0000] {task_command.py:426} INFO - Running <TaskInstance: mongodb_to_bigquery.load_orders manual__2024-08-07T14:38:14.199786+00:00 [running]> on host 721db11e5d12
[2024-08-07T14:38:30.180+0000] {taskinstance.py:2648} INFO - Exporting env vars: AIRFLOW_CTX_DAG_OWNER='***' AIRFLOW_CTX_DAG_ID='mongodb_to_bigquery' AIRFLOW_CTX_TASK_ID='load_orders' AIRFLOW_CTX_EXECUTION_DATE='2024-08-07T14:38:14.199786+00:00' AIRFLOW_CTX_TRY_NUMBER='1' AIRFLOW_CTX_DAG_RUN_ID='manual__2024-08-07T14:38:14.199786+00:00'
[2024-08-07T14:38:30.181+0000] {taskinstance.py:430} INFO - ::endgroup::
[2024-08-07T14:38:30.664+0000] {logging_mixin.py:188} INFO - ☑️ Dataset fictive_company already exists
[2024-08-07T14:38:31.039+0000] {logging_mixin.py:188} INFO - ☑️ Table mycenter-425712.fictive_company.orders already exists.
[2024-08-07T14:38:35.774+0000] {logging_mixin.py:188} INFO - 
 ✅ Loaded 2000 rows into fictive_company:orders.
[2024-08-07T14:38:36.160+0000] {logging_mixin.py:188} INFO - 
❕number rows before =  2000
[2024-08-07T14:38:37.176+0000] {taskinstance.py:441} INFO - ::group::Post task execution logs
[2024-08-07T14:38:37.189+0000] {taskinstance.py:2905} ERROR - Task failed with exception
Traceback (most recent call last):
  File "/home/airflow/.local/lib/python3.12/site-packages/airflow/models/taskinstance.py", line 465, in _execute_task
    result = _execute_callable(context=context, **execute_callable_kwargs)
             ^^^^^^^^^^^^^^^^^^^^^^^^^^^^^^^^^^^^^^^^^^^^^^^^^^^^^^^^^^^^^
  File "/home/airflow/.local/lib/python3.12/site-packages/airflow/models/taskinstance.py", line 432, in _execute_callable
    return execute_callable(context=context, **execute_callable_kwargs)
           ^^^^^^^^^^^^^^^^^^^^^^^^^^^^^^^^^^^^^^^^^^^^^^^^^^^^^^^^^^^^
  File "/home/airflow/.local/lib/python3.12/site-packages/airflow/models/baseoperator.py", line 401, in wrapper
    return func(self, *args, **kwargs)
           ^^^^^^^^^^^^^^^^^^^^^^^^^^^
  File "/home/airflow/.local/lib/python3.12/site-packages/airflow/operators/python.py", line 235, in execute
    return_value = self.execute_callable()
                   ^^^^^^^^^^^^^^^^^^^^^^^
  File "/home/airflow/.local/lib/python3.12/site-packages/airflow/operators/python.py", line 252, in execute_callable
    return self.python_callable(*self.op_args, **self.op_kwargs)
           ^^^^^^^^^^^^^^^^^^^^^^^^^^^^^^^^^^^^^^^^^^^^^^^^^^^^^
  File "/app/data_engineering/api_connectors/bigquery.py", line 80, in insert_data
    self.drop_duplicates(dataset_id,
  File "/app/data_engineering/api_connectors/bigquery.py", line 116, in drop_duplicates
    query_job.result()
  File "/home/airflow/.local/lib/python3.12/site-packages/google/cloud/bigquery/job/query.py", line 1676, in result
    while not is_job_done():
              ^^^^^^^^^^^^^
  File "/home/airflow/.local/lib/python3.12/site-packages/google/api_core/retry/retry_unary.py", line 293, in retry_wrapped_func
    return retry_target(
           ^^^^^^^^^^^^^
  File "/home/airflow/.local/lib/python3.12/site-packages/google/api_core/retry/retry_unary.py", line 153, in retry_target
    _retry_error_helper(
  File "/home/airflow/.local/lib/python3.12/site-packages/google/api_core/retry/retry_base.py", line 212, in _retry_error_helper
    raise final_exc from source_exc
  File "/home/airflow/.local/lib/python3.12/site-packages/google/api_core/retry/retry_unary.py", line 144, in retry_target
    result = target()
             ^^^^^^^^
  File "/home/airflow/.local/lib/python3.12/site-packages/google/cloud/bigquery/job/query.py", line 1625, in is_job_done
    raise job_failed_exception
google.api_core.exceptions.BadRequest: 400 Unrecognized name: created_at at [10:9]; reason: invalidQuery, location: query, message: Unrecognized name: created_at at [10:9]

Location: US
Job ID: 99275468-76ff-4ff0-9804-e8e9a36ee438

[2024-08-07T14:38:37.247+0000] {taskinstance.py:1206} INFO - Marking task as UP_FOR_RETRY. dag_id=mongodb_to_bigquery, task_id=load_orders, run_id=manual__2024-08-07T14:38:14.199786+00:00, execution_date=20240807T143814, start_date=20240807T143829, end_date=20240807T143837
[2024-08-07T14:38:37.271+0000] {standard_task_runner.py:110} ERROR - Failed to execute job 66 for task load_orders (400 Unrecognized name: created_at at [10:9]; reason: invalidQuery, location: query, message: Unrecognized name: created_at at [10:9]

Location: US
Job ID: 99275468-76ff-4ff0-9804-e8e9a36ee438
; 125)
[2024-08-07T14:38:37.319+0000] {local_task_job_runner.py:243} INFO - Task exited with return code 1
[2024-08-07T14:38:37.345+0000] {taskinstance.py:3503} INFO - 0 downstream tasks scheduled from follow-on schedule check
[2024-08-07T14:38:37.346+0000] {local_task_job_runner.py:222} INFO - ::endgroup::
